Traceback (most recent call last):
  File "/Users/ethan/opt/miniconda3/envs/pythonbook3/lib/python3.11/site-packages/jupyter_cache/executors/utils.py", line 58, in single_nb_execution
    executenb(
  File "/Users/ethan/opt/miniconda3/envs/pythonbook3/lib/python3.11/site-packages/nbclient/client.py", line 1305, in execute
    return NotebookClient(nb=nb, resources=resources, km=km, **kwargs).execute()
           ^^^^^^^^^^^^^^^^^^^^^^^^^^^^^^^^^^^^^^^^^^^^^^^^^^^^^^^^^^^^^^^^^^^^^
  File "/Users/ethan/opt/miniconda3/envs/pythonbook3/lib/python3.11/site-packages/jupyter_core/utils/__init__.py", line 173, in wrapped
    return loop.run_until_complete(inner)
           ^^^^^^^^^^^^^^^^^^^^^^^^^^^^^^
  File "/Users/ethan/opt/miniconda3/envs/pythonbook3/lib/python3.11/asyncio/base_events.py", line 653, in run_until_complete
    return future.result()
           ^^^^^^^^^^^^^^^
  File "/Users/ethan/opt/miniconda3/envs/pythonbook3/lib/python3.11/site-packages/nbclient/client.py", line 705, in async_execute
    await self.async_execute_cell(
  File "/Users/ethan/opt/miniconda3/envs/pythonbook3/lib/python3.11/site-packages/nbclient/client.py", line 1058, in async_execute_cell
    await self._check_raise_for_error(cell, cell_index, exec_reply)
  File "/Users/ethan/opt/miniconda3/envs/pythonbook3/lib/python3.11/site-packages/nbclient/client.py", line 914, in _check_raise_for_error
    raise CellExecutionError.from_cell_and_msg(cell, exec_reply_content)
nbclient.exceptions.CellExecutionError: An error occurred while executing the following cell:
------------------
M0 = smf.ols('dan_grump ~ dan_sleep + day', data=df)
M1 = smf.ols('dan_grump ~ dan_sleep + day + baby_sleep', data=df)

models = [M0, M1]
names = ['M0', 'M1']

aics = []
for n, model in enumerate(models):
    aics.append(get_aic(names[n], model))

aics
------------------


[0;31m---------------------------------------------------------------------------[0m
[0;31mNameError[0m                                 Traceback (most recent call last)
Cell [0;32mIn[64], line 9[0m
[1;32m      7[0m aics [38;5;241m=[39m []
[1;32m      8[0m [38;5;28;01mfor[39;00m n, model [38;5;129;01min[39;00m [38;5;28menumerate[39m(models):
[0;32m----> 9[0m     aics[38;5;241m.[39mappend(get_aic(names[n], model))
[1;32m     11[0m aics

[0;31mNameError[0m: name 'get_aic' is not defined

